import java.lang.ArithmeticException;
class A 
{
	public void f() throws ArithmeticException
	{
		throw new ArithmeticException();//抛出一个算术异常
	}
}
class K 
{
	public static void main(String[] args)
	{
		A aa = new A();
		try
		{
			aa.f();
		}
		catch(ArithmeticException e)
		{
			System.out.printf("\n异常具体信息是：\n");
			e.printStackTrace();
			System.out.printf("\n异常处理结果是：\n");
			System.out.printf("\n算术异常\n");
		}
	}
}

//------------------------------------------------------------
import java.lang.ArithmeticException;
class A 
{
	public void f()
	{
		try
		{
			throw new ArithmeticException();//抛出一个算术异常
		}
		catch(ArithmeticException e)
		{
			System.out.printf("\n异常具体信息是：\n");
			e.printStackTrace();
			System.out.printf("\n异常处理结果是：\n");
			System.out.printf("\n算术异常\n");
		}
		
	}
}
class K 
{
	public static void main(String[] args)
	{
		A aa = new A();
		aa.f();
	}
}